{
  size: [6, 5, 6],
  entities: [],
  blocks: [
    {
      pos: [0, 0, 0],
      state: 0
    },
    {
      pos: [5, 0, 0],
      state: 0
    },
    {
      pos: [0, 1, 0],
      state: 0
    },
    {
      pos: [1, 1, 0],
      state: 0
    },
    {
      pos: [4, 1, 0],
      state: 0
    },
    {
      pos: [5, 1, 0],
      state: 0
    },
    {
      pos: [0, 2, 0],
      state: 0
    },
    {
      pos: [1, 2, 0],
      state: 0
    },
    {
      pos: [2, 2, 0],
      state: 0
    },
    {
      pos: [3, 2, 0],
      state: 0
    },
    {
      pos: [4, 2, 0],
      state: 0
    },
    {
      pos: [5, 2, 0],
      state: 0
    },
    {
      pos: [0, 1, 1],
      state: 0
    },
    {
      pos: [5, 1, 1],
      state: 0
    },
    {
      pos: [0, 2, 1],
      state: 0
    },
    {
      pos: [1, 2, 1],
      state: 0
    },
    {
      pos: [2, 2, 1],
      state: 0
    },
    {
      pos: [3, 2, 1],
      state: 0
    },
    {
      pos: [4, 2, 1],
      state: 0
    },
    {
      pos: [5, 2, 1],
      state: 0
    },
    {
      pos: [0, 2, 2],
      state: 0
    },
    {
      pos: [1, 2, 2],
      state: 0
    },
    {
      pos: [2, 2, 2],
      state: 0
    },
    {
      pos: [3, 2, 2],
      state: 0
    },
    {
      pos: [4, 2, 2],
      state: 0
    },
    {
      pos: [5, 2, 2],
      state: 0
    },
    {
      pos: [0, 2, 3],
      state: 0
    },
    {
      pos: [1, 2, 3],
      state: 0
    },
    {
      pos: [2, 2, 3],
      state: 0
    },
    {
      pos: [3, 2, 3],
      state: 0
    },
    {
      pos: [4, 2, 3],
      state: 0
    },
    {
      pos: [5, 2, 3],
      state: 0
    },
    {
      pos: [0, 1, 4],
      state: 0
    },
    {
      pos: [5, 1, 4],
      state: 0
    },
    {
      pos: [0, 2, 4],
      state: 0
    },
    {
      pos: [1, 2, 4],
      state: 0
    },
    {
      pos: [2, 2, 4],
      state: 0
    },
    {
      pos: [3, 2, 4],
      state: 0
    },
    {
      pos: [4, 2, 4],
      state: 0
    },
    {
      pos: [5, 2, 4],
      state: 0
    },
    {
      pos: [0, 0, 5],
      state: 0
    },
    {
      pos: [5, 0, 5],
      state: 0
    },
    {
      pos: [0, 1, 5],
      state: 0
    },
    {
      pos: [1, 1, 5],
      state: 0
    },
    {
      pos: [4, 1, 5],
      state: 0
    },
    {
      pos: [5, 1, 5],
      state: 0
    },
    {
      pos: [0, 2, 5],
      state: 0
    },
    {
      pos: [1, 2, 5],
      state: 0
    },
    {
      pos: [2, 2, 5],
      state: 0
    },
    {
      pos: [3, 2, 5],
      state: 0
    },
    {
      pos: [4, 2, 5],
      state: 0
    },
    {
      pos: [5, 2, 5],
      state: 0
    },
    {
      pos: [1, 0, 0],
      state: 1
    },
    {
      pos: [2, 0, 0],
      state: 2
    },
    {
      pos: [3, 0, 0],
      state: 2
    },
    {
      pos: [4, 0, 0],
      state: 3
    },
    {
      pos: [2, 1, 0],
      state: 1
    },
    {
      pos: [3, 1, 0],
      state: 3
    },
    {
      pos: [0, 3, 0],
      state: 4
    },
    {
      pos: [1, 3, 0],
      state: 5
    },
    {
      pos: [2, 3, 0],
      state: 2
    },
    {
      pos: [3, 3, 0],
      state: 2
    },
    {
      pos: [4, 3, 0],
      state: 6
    },
    {
      pos: [5, 3, 0],
      state: 7
    },
    {
      pos: [0, 4, 0],
      state: 8
    },
    {
      pos: [1, 4, 0],
      state: 2
    },
    {
      pos: [2, 4, 0],
      state: 2
    },
    {
      pos: [3, 4, 0],
      state: 2
    },
    {
      pos: [4, 4, 0],
      state: 2
    },
    {
      pos: [5, 4, 0],
      state: 8
    },
    {
      pos: [0, 0, 1],
      state: 9
    },
    {
      pos: [1, 0, 1],
      state: 2
    },
    {
      pos: [2, 0, 1],
      state: 2
    },
    {
      pos: [3, 0, 1],
      state: 2
    },
    {
      pos: [4, 0, 1],
      state: 2
    },
    {
      pos: [5, 0, 1],
      state: 9
    },
    {
      pos: [1, 1, 1],
      state: 2
    },
    {
      pos: [2, 1, 1],
      state: 2
    },
    {
      pos: [3, 1, 1],
      state: 2
    },
    {
      pos: [4, 1, 1],
      state: 2
    },
    {
      pos: [0, 3, 1],
      state: 10
    },
    {
      pos: [1, 3, 1],
      state: 2
    },
    {
      pos: [2, 3, 1],
      state: 2
    },
    {
      pos: [3, 3, 1],
      state: 2
    },
    {
      pos: [4, 3, 1],
      state: 2
    },
    {
      pos: [5, 3, 1],
      state: 10
    },
    {
      pos: [0, 4, 1],
      state: 2
    },
    {
      pos: [1, 4, 1],
      state: 2
    },
    {
      pos: [2, 4, 1],
      state: 2
    },
    {
      pos: [3, 4, 1],
      state: 2
    },
    {
      pos: [4, 4, 1],
      state: 2
    },
    {
      pos: [5, 4, 1],
      state: 2
    },
    {
      pos: [0, 0, 2],
      state: 2
    },
    {
      pos: [1, 0, 2],
      state: 2
    },
    {
      pos: [2, 0, 2],
      state: 2
    },
    {
      pos: [3, 0, 2],
      state: 2
    },
    {
      pos: [4, 0, 2],
      state: 2
    },
    {
      pos: [5, 0, 2],
      state: 2
    },
    {
      pos: [0, 1, 2],
      state: 9
    },
    {
      pos: [1, 1, 2],
      state: 2
    },
    {
      pos: [2, 1, 2],
      state: 2
    },
    {
      pos: [3, 1, 2],
      state: 2
    },
    {
      pos: [4, 1, 2],
      state: 2
    },
    {
      pos: [5, 1, 2],
      state: 9
    },
    {
      pos: [0, 3, 2],
      state: 2
    },
    {
      pos: [1, 3, 2],
      state: 2
    },
    {
      pos: [2, 3, 2],
      state: 2
    },
    {
      pos: [3, 3, 2],
      state: 2
    },
    {
      pos: [4, 3, 2],
      state: 2
    },
    {
      pos: [5, 3, 2],
      state: 2
    },
    {
      pos: [0, 4, 2],
      state: 2
    },
    {
      pos: [1, 4, 2],
      state: 2
    },
    {
      pos: [2, 4, 2],
      state: 2
    },
    {
      pos: [3, 4, 2],
      state: 2
    },
    {
      pos: [4, 4, 2],
      state: 2
    },
    {
      pos: [5, 4, 2],
      state: 2
    },
    {
      pos: [0, 0, 3],
      state: 2
    },
    {
      pos: [1, 0, 3],
      state: 2
    },
    {
      pos: [2, 0, 3],
      state: 2
    },
    {
      pos: [3, 0, 3],
      state: 2
    },
    {
      pos: [4, 0, 3],
      state: 2
    },
    {
      pos: [5, 0, 3],
      state: 2
    },
    {
      pos: [0, 1, 3],
      state: 11
    },
    {
      pos: [1, 1, 3],
      state: 2
    },
    {
      pos: [2, 1, 3],
      state: 2
    },
    {
      pos: [3, 1, 3],
      state: 2
    },
    {
      pos: [4, 1, 3],
      state: 2
    },
    {
      pos: [5, 1, 3],
      state: 11
    },
    {
      pos: [0, 3, 3],
      state: 2
    },
    {
      pos: [1, 3, 3],
      state: 2
    },
    {
      pos: [2, 3, 3],
      state: 2
    },
    {
      pos: [3, 3, 3],
      state: 2
    },
    {
      pos: [4, 3, 3],
      state: 2
    },
    {
      pos: [5, 3, 3],
      state: 2
    },
    {
      pos: [0, 4, 3],
      state: 2
    },
    {
      pos: [1, 4, 3],
      state: 2
    },
    {
      pos: [2, 4, 3],
      state: 2
    },
    {
      pos: [3, 4, 3],
      state: 2
    },
    {
      pos: [4, 4, 3],
      state: 2
    },
    {
      pos: [5, 4, 3],
      state: 2
    },
    {
      pos: [0, 0, 4],
      state: 11
    },
    {
      pos: [1, 0, 4],
      state: 2
    },
    {
      pos: [2, 0, 4],
      state: 2
    },
    {
      pos: [3, 0, 4],
      state: 2
    },
    {
      pos: [4, 0, 4],
      state: 2
    },
    {
      pos: [5, 0, 4],
      state: 11
    },
    {
      pos: [1, 1, 4],
      state: 2
    },
    {
      pos: [2, 1, 4],
      state: 2
    },
    {
      pos: [3, 1, 4],
      state: 2
    },
    {
      pos: [4, 1, 4],
      state: 2
    },
    {
      pos: [0, 3, 4],
      state: 12
    },
    {
      pos: [1, 3, 4],
      state: 2
    },
    {
      pos: [2, 3, 4],
      state: 2
    },
    {
      pos: [3, 3, 4],
      state: 2
    },
    {
      pos: [4, 3, 4],
      state: 2
    },
    {
      pos: [5, 3, 4],
      state: 12
    },
    {
      pos: [0, 4, 4],
      state: 2
    },
    {
      pos: [1, 4, 4],
      state: 2
    },
    {
      pos: [2, 4, 4],
      state: 2
    },
    {
      pos: [3, 4, 4],
      state: 2
    },
    {
      pos: [4, 4, 4],
      state: 2
    },
    {
      pos: [5, 4, 4],
      state: 2
    },
    {
      pos: [1, 0, 5],
      state: 1
    },
    {
      pos: [2, 0, 5],
      state: 2
    },
    {
      pos: [3, 0, 5],
      state: 2
    },
    {
      pos: [4, 0, 5],
      state: 3
    },
    {
      pos: [2, 1, 5],
      state: 1
    },
    {
      pos: [3, 1, 5],
      state: 3
    },
    {
      pos: [0, 3, 5],
      state: 13
    },
    {
      pos: [1, 3, 5],
      state: 7
    },
    {
      pos: [2, 3, 5],
      state: 2
    },
    {
      pos: [3, 3, 5],
      state: 2
    },
    {
      pos: [4, 3, 5],
      state: 4
    },
    {
      pos: [5, 3, 5],
      state: 14
    },
    {
      pos: [0, 4, 5],
      state: 8
    },
    {
      pos: [1, 4, 5],
      state: 2
    },
    {
      pos: [2, 4, 5],
      state: 2
    },
    {
      pos: [3, 4, 5],
      state: 2
    },
    {
      pos: [4, 4, 5],
      state: 2
    },
    {
      pos: [5, 4, 5],
      state: 8
    }
  ],
  palette: [
    {
      Name: "minecraft:end_stone_bricks"
    },
    {
      Properties: {
        half: "top",
        waterlogged: "false",
        shape: "straight",
        facing: "west"
      },
      Name: "minecraft:end_stone_brick_stairs"
    },
    {
      Name: "minecraft:air"
    },
    {
      Properties: {
        half: "top",
        waterlogged: "false",
        shape: "straight",
        facing: "east"
      },
      Name: "minecraft:end_stone_brick_stairs"
    },
    {
      Properties: {
        east: "low",
        waterlogged: "false",
        south: "low",
        north: "none",
        west: "none",
        up: "true"
      },
      Name: "minecraft:end_stone_brick_wall"
    },
    {
      Properties: {
        east: "none",
        waterlogged: "false",
        south: "none",
        north: "none",
        west: "low",
        up: "true"
      },
      Name: "minecraft:end_stone_brick_wall"
    },
    {
      Properties: {
        east: "low",
        waterlogged: "false",
        south: "none",
        north: "none",
        west: "none",
        up: "true"
      },
      Name: "minecraft:end_stone_brick_wall"
    },
    {
      Properties: {
        east: "none",
        waterlogged: "false",
        south: "low",
        north: "none",
        west: "low",
        up: "true"
      },
      Name: "minecraft:end_stone_brick_wall"
    },
    {
      Properties: {
        facing: "up"
      },
      Name: "minecraft:end_rod"
    },
    {
      Properties: {
        half: "top",
        waterlogged: "false",
        shape: "straight",
        facing: "north"
      },
      Name: "minecraft:end_stone_brick_stairs"
    },
    {
      Properties: {
        east: "none",
        waterlogged: "false",
        south: "none",
        north: "low",
        west: "none",
        up: "true"
      },
      Name: "minecraft:end_stone_brick_wall"
    },
    {
      Properties: {
        half: "top",
        waterlogged: "false",
        shape: "straight",
        facing: "south"
      },
      Name: "minecraft:end_stone_brick_stairs"
    },
    {
      Properties: {
        east: "none",
        waterlogged: "false",
        south: "low",
        north: "none",
        west: "none",
        up: "true"
      },
      Name: "minecraft:end_stone_brick_wall"
    },
    {
      Properties: {
        east: "low",
        waterlogged: "false",
        south: "none",
        north: "low",
        west: "none",
        up: "true"
      },
      Name: "minecraft:end_stone_brick_wall"
    },
    {
      Properties: {
        east: "none",
        waterlogged: "false",
        south: "none",
        north: "low",
        west: "low",
        up: "true"
      },
      Name: "minecraft:end_stone_brick_wall"
    }
  ],
  DataVersion: 2519
}