{
  size: [6, 12, 7],
  entities: [],
  blocks: [
    {
      pos: [1, 8, 0],
      state: 0
    },
    {
      pos: [2, 8, 0],
      state: 1
    },
    {
      pos: [3, 8, 0],
      state: 0
    },
    {
      pos: [4, 8, 0],
      state: 2
    },
    {
      pos: [1, 9, 0],
      state: 0
    },
    {
      pos: [2, 9, 0],
      state: 1
    },
    {
      pos: [3, 9, 0],
      state: 0
    },
    {
      pos: [4, 9, 0],
      state: 2
    },
    {
      pos: [2, 4, 1],
      state: 3
    },
    {
      pos: [3, 4, 1],
      state: 3
    },
    {
      pos: [0, 8, 1],
      state: 0
    },
    {
      pos: [1, 8, 1],
      state: 1
    },
    {
      pos: [2, 8, 1],
      state: 4
    },
    {
      pos: [3, 8, 1],
      state: 1
    },
    {
      pos: [4, 8, 1],
      state: 0
    },
    {
      pos: [0, 9, 1],
      state: 0
    },
    {
      pos: [1, 9, 1],
      state: 1
    },
    {
      pos: [2, 9, 1],
      state: 4
    },
    {
      pos: [3, 9, 1],
      state: 1
    },
    {
      pos: [4, 9, 1],
      state: 0
    },
    {
      pos: [1, 10, 1],
      state: 1
    },
    {
      pos: [2, 10, 1],
      state: 4
    },
    {
      pos: [2, 11, 1],
      state: 1
    },
    {
      pos: [2, 2, 2],
      state: 5
    },
    {
      pos: [1, 3, 2],
      state: 5
    },
    {
      pos: [2, 3, 2],
      state: 5
    },
    {
      pos: [3, 3, 2],
      state: 5
    },
    {
      pos: [4, 3, 2],
      state: 5
    },
    {
      pos: [1, 4, 2],
      state: 3
    },
    {
      pos: [2, 4, 2],
      state: 5
    },
    {
      pos: [3, 4, 2],
      state: 3
    },
    {
      pos: [4, 4, 2],
      state: 3
    },
    {
      pos: [2, 5, 2],
      state: 6
    },
    {
      pos: [2, 6, 2],
      state: 6
    },
    {
      pos: [2, 7, 2],
      state: 6
    },
    {
      pos: [0, 8, 2],
      state: 1
    },
    {
      pos: [1, 8, 2],
      state: 4
    },
    {
      pos: [2, 8, 2],
      state: 6
    },
    {
      pos: [3, 8, 2],
      state: 4
    },
    {
      pos: [4, 8, 2],
      state: 1
    },
    {
      pos: [0, 9, 2],
      state: 1
    },
    {
      pos: [1, 9, 2],
      state: 4
    },
    {
      pos: [2, 9, 2],
      state: 6
    },
    {
      pos: [3, 9, 2],
      state: 4
    },
    {
      pos: [4, 9, 2],
      state: 1
    },
    {
      pos: [1, 10, 2],
      state: 4
    },
    {
      pos: [2, 10, 2],
      state: 6
    },
    {
      pos: [3, 10, 2],
      state: 4
    },
    {
      pos: [1, 11, 2],
      state: 1
    },
    {
      pos: [2, 11, 2],
      state: 4
    },
    {
      pos: [3, 11, 2],
      state: 1
    },
    {
      pos: [2, 1, 3],
      state: 5
    },
    {
      pos: [2, 2, 3],
      state: 5
    },
    {
      pos: [3, 2, 3],
      state: 5
    },
    {
      pos: [2, 3, 3],
      state: 5
    },
    {
      pos: [3, 3, 3],
      state: 5
    },
    {
      pos: [4, 3, 3],
      state: 5
    },
    {
      pos: [2, 4, 3],
      state: 3
    },
    {
      pos: [3, 4, 3],
      state: 3
    },
    {
      pos: [4, 4, 3],
      state: 3
    },
    {
      pos: [5, 4, 3],
      state: 3
    },
    {
      pos: [0, 8, 3],
      state: 0
    },
    {
      pos: [1, 8, 3],
      state: 1
    },
    {
      pos: [2, 8, 3],
      state: 4
    },
    {
      pos: [3, 8, 3],
      state: 1
    },
    {
      pos: [4, 8, 3],
      state: 0
    },
    {
      pos: [0, 9, 3],
      state: 0
    },
    {
      pos: [1, 9, 3],
      state: 1
    },
    {
      pos: [2, 9, 3],
      state: 4
    },
    {
      pos: [3, 9, 3],
      state: 1
    },
    {
      pos: [4, 9, 3],
      state: 0
    },
    {
      pos: [2, 10, 3],
      state: 4
    },
    {
      pos: [2, 11, 3],
      state: 1
    },
    {
      pos: [1, 0, 4],
      state: 5
    },
    {
      pos: [1, 1, 4],
      state: 5
    },
    {
      pos: [1, 2, 4],
      state: 5
    },
    {
      pos: [2, 2, 4],
      state: 5
    },
    {
      pos: [3, 2, 4],
      state: 5
    },
    {
      pos: [1, 3, 4],
      state: 5
    },
    {
      pos: [2, 3, 4],
      state: 5
    },
    {
      pos: [3, 3, 4],
      state: 5
    },
    {
      pos: [4, 3, 4],
      state: 5
    },
    {
      pos: [1, 4, 4],
      state: 3
    },
    {
      pos: [2, 4, 4],
      state: 3
    },
    {
      pos: [3, 4, 4],
      state: 3
    },
    {
      pos: [4, 4, 4],
      state: 3
    },
    {
      pos: [1, 8, 4],
      state: 0
    },
    {
      pos: [2, 8, 4],
      state: 1
    },
    {
      pos: [3, 8, 4],
      state: 0
    },
    {
      pos: [0, 9, 4],
      state: 2
    },
    {
      pos: [1, 9, 4],
      state: 0
    },
    {
      pos: [2, 9, 4],
      state: 1
    },
    {
      pos: [3, 9, 4],
      state: 0
    },
    {
      pos: [4, 9, 4],
      state: 2
    },
    {
      pos: [2, 3, 5],
      state: 5
    },
    {
      pos: [2, 4, 5],
      state: 3
    },
    {
      pos: [3, 4, 5],
      state: 3
    },
    {
      pos: [2, 4, 6],
      state: 3
    },
    {
      nbt: {
        Items: [
          {
            Slot: 3b,
            id: "minecraft:lava_bucket",
            Count: 1b
          },
          {
            Slot: 4b,
            id: "minecraft:beacon",
            Count: 1b
          },
          {
            Slot: 5b,
            id: "minecraft:pufferfish_bucket",
            Count: 1b
          },
          {
            Slot: 12b,
            id: "minecraft:pumpkin",
            Count: 1b
          },
          {
            Slot: 13b,
            id: "minecraft:sugar_cane",
            Count: 1b
          },
          {
            Slot: 14b,
            id: "minecraft:melon_slice",
            Count: 1b
          },
          {
            Slot: 22b,
            id: "minecraft:book_box",
            Count: 1b
          }
        ],
        id: "minecraft:chest"
      },
      pos: [2, 5, 6],
      state: 7
    },
    {
      pos: [0, 0, 0],
      state: 8
    },
    {
      pos: [1, 0, 0],
      state: 8
    },
    {
      pos: [2, 0, 0],
      state: 8
    },
    {
      pos: [3, 0, 0],
      state: 8
    },
    {
      pos: [4, 0, 0],
      state: 8
    },
    {
      pos: [5, 0, 0],
      state: 8
    },
    {
      pos: [0, 1, 0],
      state: 8
    },
    {
      pos: [1, 1, 0],
      state: 8
    },
    {
      pos: [2, 1, 0],
      state: 8
    },
    {
      pos: [3, 1, 0],
      state: 8
    },
    {
      pos: [4, 1, 0],
      state: 8
    },
    {
      pos: [5, 1, 0],
      state: 8
    },
    {
      pos: [0, 2, 0],
      state: 8
    },
    {
      pos: [1, 2, 0],
      state: 8
    },
    {
      pos: [2, 2, 0],
      state: 8
    },
    {
      pos: [3, 2, 0],
      state: 8
    },
    {
      pos: [4, 2, 0],
      state: 8
    },
    {
      pos: [5, 2, 0],
      state: 8
    },
    {
      pos: [0, 3, 0],
      state: 8
    },
    {
      pos: [1, 3, 0],
      state: 8
    },
    {
      pos: [2, 3, 0],
      state: 8
    },
    {
      pos: [3, 3, 0],
      state: 8
    },
    {
      pos: [4, 3, 0],
      state: 8
    },
    {
      pos: [5, 3, 0],
      state: 8
    },
    {
      pos: [0, 4, 0],
      state: 8
    },
    {
      pos: [1, 4, 0],
      state: 8
    },
    {
      pos: [2, 4, 0],
      state: 8
    },
    {
      pos: [3, 4, 0],
      state: 8
    },
    {
      pos: [4, 4, 0],
      state: 8
    },
    {
      pos: [5, 4, 0],
      state: 8
    },
    {
      pos: [0, 5, 0],
      state: 8
    },
    {
      pos: [1, 5, 0],
      state: 8
    },
    {
      pos: [2, 5, 0],
      state: 8
    },
    {
      pos: [3, 5, 0],
      state: 8
    },
    {
      pos: [4, 5, 0],
      state: 8
    },
    {
      pos: [5, 5, 0],
      state: 8
    },
    {
      pos: [0, 6, 0],
      state: 8
    },
    {
      pos: [1, 6, 0],
      state: 8
    },
    {
      pos: [2, 6, 0],
      state: 8
    },
    {
      pos: [3, 6, 0],
      state: 8
    },
    {
      pos: [4, 6, 0],
      state: 8
    },
    {
      pos: [5, 6, 0],
      state: 8
    },
    {
      pos: [0, 7, 0],
      state: 8
    },
    {
      pos: [1, 7, 0],
      state: 8
    },
    {
      pos: [2, 7, 0],
      state: 8
    },
    {
      pos: [3, 7, 0],
      state: 8
    },
    {
      pos: [4, 7, 0],
      state: 8
    },
    {
      pos: [5, 7, 0],
      state: 8
    },
    {
      pos: [0, 8, 0],
      state: 8
    },
    {
      pos: [5, 8, 0],
      state: 8
    },
    {
      pos: [0, 9, 0],
      state: 8
    },
    {
      pos: [5, 9, 0],
      state: 8
    },
    {
      pos: [0, 10, 0],
      state: 8
    },
    {
      pos: [1, 10, 0],
      state: 8
    },
    {
      pos: [2, 10, 0],
      state: 8
    },
    {
      pos: [3, 10, 0],
      state: 8
    },
    {
      pos: [4, 10, 0],
      state: 8
    },
    {
      pos: [5, 10, 0],
      state: 8
    },
    {
      pos: [0, 11, 0],
      state: 8
    },
    {
      pos: [1, 11, 0],
      state: 8
    },
    {
      pos: [2, 11, 0],
      state: 8
    },
    {
      pos: [3, 11, 0],
      state: 8
    },
    {
      pos: [4, 11, 0],
      state: 8
    },
    {
      pos: [5, 11, 0],
      state: 8
    },
    {
      pos: [0, 0, 1],
      state: 8
    },
    {
      pos: [1, 0, 1],
      state: 8
    },
    {
      pos: [2, 0, 1],
      state: 8
    },
    {
      pos: [3, 0, 1],
      state: 8
    },
    {
      pos: [4, 0, 1],
      state: 8
    },
    {
      pos: [5, 0, 1],
      state: 8
    },
    {
      pos: [0, 1, 1],
      state: 8
    },
    {
      pos: [1, 1, 1],
      state: 8
    },
    {
      pos: [2, 1, 1],
      state: 8
    },
    {
      pos: [3, 1, 1],
      state: 8
    },
    {
      pos: [4, 1, 1],
      state: 8
    },
    {
      pos: [5, 1, 1],
      state: 8
    },
    {
      pos: [0, 2, 1],
      state: 8
    },
    {
      pos: [1, 2, 1],
      state: 8
    },
    {
      pos: [2, 2, 1],
      state: 8
    },
    {
      pos: [3, 2, 1],
      state: 8
    },
    {
      pos: [4, 2, 1],
      state: 8
    },
    {
      pos: [5, 2, 1],
      state: 8
    },
    {
      pos: [0, 3, 1],
      state: 8
    },
    {
      pos: [1, 3, 1],
      state: 8
    },
    {
      pos: [2, 3, 1],
      state: 8
    },
    {
      pos: [3, 3, 1],
      state: 8
    },
    {
      pos: [4, 3, 1],
      state: 8
    },
    {
      pos: [5, 3, 1],
      state: 8
    },
    {
      pos: [0, 4, 1],
      state: 8
    },
    {
      pos: [1, 4, 1],
      state: 8
    },
    {
      pos: [4, 4, 1],
      state: 8
    },
    {
      pos: [5, 4, 1],
      state: 8
    },
    {
      pos: [0, 5, 1],
      state: 8
    },
    {
      pos: [1, 5, 1],
      state: 8
    },
    {
      pos: [2, 5, 1],
      state: 8
    },
    {
      pos: [3, 5, 1],
      state: 8
    },
    {
      pos: [4, 5, 1],
      state: 8
    },
    {
      pos: [5, 5, 1],
      state: 8
    },
    {
      pos: [0, 6, 1],
      state: 8
    },
    {
      pos: [1, 6, 1],
      state: 8
    },
    {
      pos: [2, 6, 1],
      state: 8
    },
    {
      pos: [3, 6, 1],
      state: 8
    },
    {
      pos: [4, 6, 1],
      state: 8
    },
    {
      pos: [5, 6, 1],
      state: 8
    },
    {
      pos: [0, 7, 1],
      state: 8
    },
    {
      pos: [1, 7, 1],
      state: 8
    },
    {
      pos: [2, 7, 1],
      state: 8
    },
    {
      pos: [3, 7, 1],
      state: 8
    },
    {
      pos: [4, 7, 1],
      state: 8
    },
    {
      pos: [5, 7, 1],
      state: 8
    },
    {
      pos: [5, 8, 1],
      state: 8
    },
    {
      pos: [5, 9, 1],
      state: 8
    },
    {
      pos: [0, 10, 1],
      state: 8
    },
    {
      pos: [3, 10, 1],
      state: 8
    },
    {
      pos: [4, 10, 1],
      state: 8
    },
    {
      pos: [5, 10, 1],
      state: 8
    },
    {
      pos: [0, 11, 1],
      state: 8
    },
    {
      pos: [1, 11, 1],
      state: 8
    },
    {
      pos: [3, 11, 1],
      state: 8
    },
    {
      pos: [4, 11, 1],
      state: 8
    },
    {
      pos: [5, 11, 1],
      state: 8
    },
    {
      pos: [0, 0, 2],
      state: 8
    },
    {
      pos: [1, 0, 2],
      state: 8
    },
    {
      pos: [2, 0, 2],
      state: 8
    },
    {
      pos: [3, 0, 2],
      state: 8
    },
    {
      pos: [4, 0, 2],
      state: 8
    },
    {
      pos: [5, 0, 2],
      state: 8
    },
    {
      pos: [0, 1, 2],
      state: 8
    },
    {
      pos: [1, 1, 2],
      state: 8
    },
    {
      pos: [2, 1, 2],
      state: 8
    },
    {
      pos: [3, 1, 2],
      state: 8
    },
    {
      pos: [4, 1, 2],
      state: 8
    },
    {
      pos: [5, 1, 2],
      state: 8
    },
    {
      pos: [0, 2, 2],
      state: 8
    },
    {
      pos: [1, 2, 2],
      state: 8
    },
    {
      pos: [3, 2, 2],
      state: 8
    },
    {
      pos: [4, 2, 2],
      state: 8
    },
    {
      pos: [5, 2, 2],
      state: 8
    },
    {
      pos: [0, 3, 2],
      state: 8
    },
    {
      pos: [5, 3, 2],
      state: 8
    },
    {
      pos: [0, 4, 2],
      state: 8
    },
    {
      pos: [5, 4, 2],
      state: 8
    },
    {
      pos: [0, 5, 2],
      state: 8
    },
    {
      pos: [1, 5, 2],
      state: 8
    },
    {
      pos: [3, 5, 2],
      state: 8
    },
    {
      pos: [4, 5, 2],
      state: 8
    },
    {
      pos: [5, 5, 2],
      state: 8
    },
    {
      pos: [0, 6, 2],
      state: 8
    },
    {
      pos: [1, 6, 2],
      state: 8
    },
    {
      pos: [3, 6, 2],
      state: 8
    },
    {
      pos: [4, 6, 2],
      state: 8
    },
    {
      pos: [5, 6, 2],
      state: 8
    },
    {
      pos: [0, 7, 2],
      state: 8
    },
    {
      pos: [1, 7, 2],
      state: 8
    },
    {
      pos: [3, 7, 2],
      state: 8
    },
    {
      pos: [4, 7, 2],
      state: 8
    },
    {
      pos: [5, 7, 2],
      state: 8
    },
    {
      pos: [5, 8, 2],
      state: 8
    },
    {
      pos: [5, 9, 2],
      state: 8
    },
    {
      pos: [0, 10, 2],
      state: 8
    },
    {
      pos: [4, 10, 2],
      state: 8
    },
    {
      pos: [5, 10, 2],
      state: 8
    },
    {
      pos: [0, 11, 2],
      state: 8
    },
    {
      pos: [4, 11, 2],
      state: 8
    },
    {
      pos: [5, 11, 2],
      state: 8
    },
    {
      pos: [0, 0, 3],
      state: 8
    },
    {
      pos: [1, 0, 3],
      state: 8
    },
    {
      pos: [2, 0, 3],
      state: 8
    },
    {
      pos: [3, 0, 3],
      state: 8
    },
    {
      pos: [4, 0, 3],
      state: 8
    },
    {
      pos: [5, 0, 3],
      state: 8
    },
    {
      pos: [0, 1, 3],
      state: 8
    },
    {
      pos: [1, 1, 3],
      state: 8
    },
    {
      pos: [3, 1, 3],
      state: 8
    },
    {
      pos: [4, 1, 3],
      state: 8
    },
    {
      pos: [5, 1, 3],
      state: 8
    },
    {
      pos: [0, 2, 3],
      state: 8
    },
    {
      pos: [1, 2, 3],
      state: 8
    },
    {
      pos: [4, 2, 3],
      state: 8
    },
    {
      pos: [5, 2, 3],
      state: 8
    },
    {
      pos: [0, 3, 3],
      state: 8
    },
    {
      pos: [1, 3, 3],
      state: 8
    },
    {
      pos: [5, 3, 3],
      state: 8
    },
    {
      pos: [0, 4, 3],
      state: 8
    },
    {
      pos: [1, 4, 3],
      state: 8
    },
    {
      pos: [0, 5, 3],
      state: 8
    },
    {
      pos: [1, 5, 3],
      state: 8
    },
    {
      pos: [2, 5, 3],
      state: 8
    },
    {
      pos: [3, 5, 3],
      state: 8
    },
    {
      pos: [4, 5, 3],
      state: 8
    },
    {
      pos: [5, 5, 3],
      state: 8
    },
    {
      pos: [0, 6, 3],
      state: 8
    },
    {
      pos: [1, 6, 3],
      state: 8
    },
    {
      pos: [2, 6, 3],
      state: 8
    },
    {
      pos: [3, 6, 3],
      state: 8
    },
    {
      pos: [4, 6, 3],
      state: 8
    },
    {
      pos: [5, 6, 3],
      state: 8
    },
    {
      pos: [0, 7, 3],
      state: 8
    },
    {
      pos: [1, 7, 3],
      state: 8
    },
    {
      pos: [2, 7, 3],
      state: 8
    },
    {
      pos: [3, 7, 3],
      state: 8
    },
    {
      pos: [4, 7, 3],
      state: 8
    },
    {
      pos: [5, 7, 3],
      state: 8
    },
    {
      pos: [5, 8, 3],
      state: 8
    },
    {
      pos: [5, 9, 3],
      state: 8
    },
    {
      pos: [0, 10, 3],
      state: 8
    },
    {
      pos: [1, 10, 3],
      state: 8
    },
    {
      pos: [3, 10, 3],
      state: 8
    },
    {
      pos: [4, 10, 3],
      state: 8
    },
    {
      pos: [5, 10, 3],
      state: 8
    },
    {
      pos: [0, 11, 3],
      state: 8
    },
    {
      pos: [1, 11, 3],
      state: 8
    },
    {
      pos: [3, 11, 3],
      state: 8
    },
    {
      pos: [4, 11, 3],
      state: 8
    },
    {
      pos: [5, 11, 3],
      state: 8
    },
    {
      pos: [0, 0, 4],
      state: 8
    },
    {
      pos: [2, 0, 4],
      state: 8
    },
    {
      pos: [3, 0, 4],
      state: 8
    },
    {
      pos: [4, 0, 4],
      state: 8
    },
    {
      pos: [5, 0, 4],
      state: 8
    },
    {
      pos: [0, 1, 4],
      state: 8
    },
    {
      pos: [2, 1, 4],
      state: 8
    },
    {
      pos: [3, 1, 4],
      state: 8
    },
    {
      pos: [4, 1, 4],
      state: 8
    },
    {
      pos: [5, 1, 4],
      state: 8
    },
    {
      pos: [0, 2, 4],
      state: 8
    },
    {
      pos: [4, 2, 4],
      state: 8
    },
    {
      pos: [5, 2, 4],
      state: 8
    },
    {
      pos: [0, 3, 4],
      state: 8
    },
    {
      pos: [5, 3, 4],
      state: 8
    },
    {
      pos: [0, 4, 4],
      state: 8
    },
    {
      pos: [5, 4, 4],
      state: 8
    },
    {
      pos: [0, 5, 4],
      state: 8
    },
    {
      pos: [1, 5, 4],
      state: 8
    },
    {
      pos: [2, 5, 4],
      state: 8
    },
    {
      pos: [3, 5, 4],
      state: 8
    },
    {
      pos: [4, 5, 4],
      state: 8
    },
    {
      pos: [5, 5, 4],
      state: 8
    },
    {
      pos: [0, 6, 4],
      state: 8
    },
    {
      pos: [1, 6, 4],
      state: 8
    },
    {
      pos: [2, 6, 4],
      state: 8
    },
    {
      pos: [3, 6, 4],
      state: 8
    },
    {
      pos: [4, 6, 4],
      state: 8
    },
    {
      pos: [5, 6, 4],
      state: 8
    },
    {
      pos: [0, 7, 4],
      state: 8
    },
    {
      pos: [1, 7, 4],
      state: 8
    },
    {
      pos: [2, 7, 4],
      state: 8
    },
    {
      pos: [3, 7, 4],
      state: 8
    },
    {
      pos: [4, 7, 4],
      state: 8
    },
    {
      pos: [5, 7, 4],
      state: 8
    },
    {
      pos: [0, 8, 4],
      state: 8
    },
    {
      pos: [4, 8, 4],
      state: 8
    },
    {
      pos: [5, 8, 4],
      state: 8
    },
    {
      pos: [5, 9, 4],
      state: 8
    },
    {
      pos: [0, 10, 4],
      state: 8
    },
    {
      pos: [1, 10, 4],
      state: 8
    },
    {
      pos: [2, 10, 4],
      state: 8
    },
    {
      pos: [3, 10, 4],
      state: 8
    },
    {
      pos: [4, 10, 4],
      state: 8
    },
    {
      pos: [5, 10, 4],
      state: 8
    },
    {
      pos: [0, 11, 4],
      state: 8
    },
    {
      pos: [1, 11, 4],
      state: 8
    },
    {
      pos: [2, 11, 4],
      state: 8
    },
    {
      pos: [3, 11, 4],
      state: 8
    },
    {
      pos: [4, 11, 4],
      state: 8
    },
    {
      pos: [5, 11, 4],
      state: 8
    },
    {
      pos: [0, 0, 5],
      state: 8
    },
    {
      pos: [1, 0, 5],
      state: 8
    },
    {
      pos: [2, 0, 5],
      state: 8
    },
    {
      pos: [3, 0, 5],
      state: 8
    },
    {
      pos: [4, 0, 5],
      state: 8
    },
    {
      pos: [5, 0, 5],
      state: 8
    },
    {
      pos: [0, 1, 5],
      state: 8
    },
    {
      pos: [1, 1, 5],
      state: 8
    },
    {
      pos: [2, 1, 5],
      state: 8
    },
    {
      pos: [3, 1, 5],
      state: 8
    },
    {
      pos: [4, 1, 5],
      state: 8
    },
    {
      pos: [5, 1, 5],
      state: 8
    },
    {
      pos: [0, 2, 5],
      state: 8
    },
    {
      pos: [1, 2, 5],
      state: 8
    },
    {
      pos: [2, 2, 5],
      state: 8
    },
    {
      pos: [3, 2, 5],
      state: 8
    },
    {
      pos: [4, 2, 5],
      state: 8
    },
    {
      pos: [5, 2, 5],
      state: 8
    },
    {
      pos: [0, 3, 5],
      state: 8
    },
    {
      pos: [1, 3, 5],
      state: 8
    },
    {
      pos: [3, 3, 5],
      state: 8
    },
    {
      pos: [4, 3, 5],
      state: 8
    },
    {
      pos: [5, 3, 5],
      state: 8
    },
    {
      pos: [0, 4, 5],
      state: 8
    },
    {
      pos: [1, 4, 5],
      state: 8
    },
    {
      pos: [4, 4, 5],
      state: 8
    },
    {
      pos: [5, 4, 5],
      state: 8
    },
    {
      pos: [0, 5, 5],
      state: 8
    },
    {
      pos: [1, 5, 5],
      state: 8
    },
    {
      pos: [2, 5, 5],
      state: 8
    },
    {
      pos: [3, 5, 5],
      state: 8
    },
    {
      pos: [4, 5, 5],
      state: 8
    },
    {
      pos: [5, 5, 5],
      state: 8
    },
    {
      pos: [0, 6, 5],
      state: 8
    },
    {
      pos: [1, 6, 5],
      state: 8
    },
    {
      pos: [2, 6, 5],
      state: 8
    },
    {
      pos: [3, 6, 5],
      state: 8
    },
    {
      pos: [4, 6, 5],
      state: 8
    },
    {
      pos: [5, 6, 5],
      state: 8
    },
    {
      pos: [0, 7, 5],
      state: 8
    },
    {
      pos: [1, 7, 5],
      state: 8
    },
    {
      pos: [2, 7, 5],
      state: 8
    },
    {
      pos: [3, 7, 5],
      state: 8
    },
    {
      pos: [4, 7, 5],
      state: 8
    },
    {
      pos: [5, 7, 5],
      state: 8
    },
    {
      pos: [0, 8, 5],
      state: 8
    },
    {
      pos: [1, 8, 5],
      state: 8
    },
    {
      pos: [2, 8, 5],
      state: 8
    },
    {
      pos: [3, 8, 5],
      state: 8
    },
    {
      pos: [4, 8, 5],
      state: 8
    },
    {
      pos: [5, 8, 5],
      state: 8
    },
    {
      pos: [0, 9, 5],
      state: 8
    },
    {
      pos: [1, 9, 5],
      state: 8
    },
    {
      pos: [2, 9, 5],
      state: 8
    },
    {
      pos: [3, 9, 5],
      state: 8
    },
    {
      pos: [4, 9, 5],
      state: 8
    },
    {
      pos: [5, 9, 5],
      state: 8
    },
    {
      pos: [0, 10, 5],
      state: 8
    },
    {
      pos: [1, 10, 5],
      state: 8
    },
    {
      pos: [2, 10, 5],
      state: 8
    },
    {
      pos: [3, 10, 5],
      state: 8
    },
    {
      pos: [4, 10, 5],
      state: 8
    },
    {
      pos: [5, 10, 5],
      state: 8
    },
    {
      pos: [0, 11, 5],
      state: 8
    },
    {
      pos: [1, 11, 5],
      state: 8
    },
    {
      pos: [2, 11, 5],
      state: 8
    },
    {
      pos: [3, 11, 5],
      state: 8
    },
    {
      pos: [4, 11, 5],
      state: 8
    },
    {
      pos: [5, 11, 5],
      state: 8
    },
    {
      pos: [0, 0, 6],
      state: 8
    },
    {
      pos: [1, 0, 6],
      state: 8
    },
    {
      pos: [2, 0, 6],
      state: 8
    },
    {
      pos: [3, 0, 6],
      state: 8
    },
    {
      pos: [4, 0, 6],
      state: 8
    },
    {
      pos: [5, 0, 6],
      state: 8
    },
    {
      pos: [0, 1, 6],
      state: 8
    },
    {
      pos: [1, 1, 6],
      state: 8
    },
    {
      pos: [2, 1, 6],
      state: 8
    },
    {
      pos: [3, 1, 6],
      state: 8
    },
    {
      pos: [4, 1, 6],
      state: 8
    },
    {
      pos: [5, 1, 6],
      state: 8
    },
    {
      pos: [0, 2, 6],
      state: 8
    },
    {
      pos: [1, 2, 6],
      state: 8
    },
    {
      pos: [2, 2, 6],
      state: 8
    },
    {
      pos: [3, 2, 6],
      state: 8
    },
    {
      pos: [4, 2, 6],
      state: 8
    },
    {
      pos: [5, 2, 6],
      state: 8
    },
    {
      pos: [0, 3, 6],
      state: 8
    },
    {
      pos: [1, 3, 6],
      state: 8
    },
    {
      pos: [2, 3, 6],
      state: 8
    },
    {
      pos: [3, 3, 6],
      state: 8
    },
    {
      pos: [4, 3, 6],
      state: 8
    },
    {
      pos: [5, 3, 6],
      state: 8
    },
    {
      pos: [0, 4, 6],
      state: 8
    },
    {
      pos: [1, 4, 6],
      state: 8
    },
    {
      pos: [3, 4, 6],
      state: 8
    },
    {
      pos: [4, 4, 6],
      state: 8
    },
    {
      pos: [5, 4, 6],
      state: 8
    },
    {
      pos: [0, 5, 6],
      state: 8
    },
    {
      pos: [1, 5, 6],
      state: 8
    },
    {
      pos: [3, 5, 6],
      state: 8
    },
    {
      pos: [4, 5, 6],
      state: 8
    },
    {
      pos: [5, 5, 6],
      state: 8
    },
    {
      pos: [0, 6, 6],
      state: 8
    },
    {
      pos: [1, 6, 6],
      state: 8
    },
    {
      pos: [2, 6, 6],
      state: 8
    },
    {
      pos: [3, 6, 6],
      state: 8
    },
    {
      pos: [4, 6, 6],
      state: 8
    },
    {
      pos: [5, 6, 6],
      state: 8
    },
    {
      pos: [0, 7, 6],
      state: 8
    },
    {
      pos: [1, 7, 6],
      state: 8
    },
    {
      pos: [2, 7, 6],
      state: 8
    },
    {
      pos: [3, 7, 6],
      state: 8
    },
    {
      pos: [4, 7, 6],
      state: 8
    },
    {
      pos: [5, 7, 6],
      state: 8
    },
    {
      pos: [0, 8, 6],
      state: 8
    },
    {
      pos: [1, 8, 6],
      state: 8
    },
    {
      pos: [2, 8, 6],
      state: 8
    },
    {
      pos: [3, 8, 6],
      state: 8
    },
    {
      pos: [4, 8, 6],
      state: 8
    },
    {
      pos: [5, 8, 6],
      state: 8
    },
    {
      pos: [0, 9, 6],
      state: 8
    },
    {
      pos: [1, 9, 6],
      state: 8
    },
    {
      pos: [2, 9, 6],
      state: 8
    },
    {
      pos: [3, 9, 6],
      state: 8
    },
    {
      pos: [4, 9, 6],
      state: 8
    },
    {
      pos: [5, 9, 6],
      state: 8
    },
    {
      pos: [0, 10, 6],
      state: 8
    },
    {
      pos: [1, 10, 6],
      state: 8
    },
    {
      pos: [2, 10, 6],
      state: 8
    },
    {
      pos: [3, 10, 6],
      state: 8
    },
    {
      pos: [4, 10, 6],
      state: 8
    },
    {
      pos: [5, 10, 6],
      state: 8
    },
    {
      pos: [0, 11, 6],
      state: 8
    },
    {
      pos: [1, 11, 6],
      state: 8
    },
    {
      pos: [2, 11, 6],
      state: 8
    },
    {
      pos: [3, 11, 6],
      state: 8
    },
    {
      pos: [4, 11, 6],
      state: 8
    },
    {
      pos: [5, 11, 6],
      state: 8
    }
  ],
  palette: [
    {
      Properties: {
        distance: "3",
        persistent: "false"
      },
      Name: "minecraft:oak_leaves"
    },
    {
      Properties: {
        distance: "2",
        persistent: "false"
      },
      Name: "minecraft:oak_leaves"
    },
    {
      Properties: {
        distance: "4",
        persistent: "false"
      },
      Name: "minecraft:oak_leaves"
    },
    {
      Properties: {
        snowy: "false"
      },
      Name: "minecraft:grass_block"
    },
    {
      Properties: {
        distance: "1",
        persistent: "false"
      },
      Name: "minecraft:oak_leaves"
    },
    {
      Name: "minecraft:dirt"
    },
    {
      Properties: {
        axis: "y"
      },
      Name: "minecraft:oak_log"
    },
    {
      Properties: {
        waterlogged: "false",
        facing: "north",
        type: "single"
      },
      Name: "minecraft:chest"
    },
    {
      Name: "minecraft:air"
    }
  ],
  DataVersion: 2519
}