{
  size: [8, 5, 10],
  entities: [
    {
      nbt: {
        Brain: {
          memories: {}
        },
        HurtByTimestamp: 0,
        Tame: 0b,
        Attributes: [
          {
            Base: 25.0d,
            Name: "generic.maxHealth"
          },
          {
            Base: 0.0d,
            Name: "generic.knockbackResistance"
          },
          {
            Base: 0.17499999701976776d,
            Name: "generic.movementSpeed"
          },
          {
            Base: 0.0d,
            Name: "generic.armor"
          },
          {
            Base: 0.0d,
            Name: "generic.armorToughness"
          },
          {
            Base: 40.0d,
            Modifiers: [
              {
                Amount: 0.007510913693520235d,
                Operation: 1,
                UUID: [I; 1448961065, -354989116, -1679294657, -693590412],
                Name: "Random spawn bonus"
              }
            ],
            Name: "generic.followRange"
          },
          {
            Base: 0.0d,
            Name: "generic.attackKnockback"
          },
          {
            Base: 0.5d,
            Name: "horse.jumpStrength"
          }
        ],
        Invulnerable: 0b,
        FallFlying: 0b,
        ForcedAge: 0,
        PortalCooldown: 0,
        AbsorptionAmount: 0.0f,
        Bred: 0b,
        FallDistance: 0.0f,
        InLove: 0,
        EatingHaystack: 0b,
        DeathTime: 0s,
        DecorItem: {
          id: "minecraft:lime_carpet",
          Count: 1b
        },
        HandDropChances: [0.08500000089406967f, 0.08500000089406967f],
        PersistenceRequired: 0b,
        id: "minecraft:llama",
        UUID: [I; 1958838548, 528239893, -1644753722, 1878349677],
        Age: 0,
        Motion: [0.0d, -0.0784000015258789d, 0.0d],
        Health: 25.0f,
        LeftHanded: 0b,
        Air: 300s,
        OnGround: 1b,
        Dimension: 0,
        Rotation: [271.43280029296875f, 0.0f],
        HandItems: [
          {},
          {}
        ],
        Variant: 1,
        ArmorDropChances: [0.08500000089406967f, 0.08500000089406967f, 0.08500000089406967f, 0.08500000089406967f],
        Pos: [-216.90010162846824d, 57.0d, 85.48877659428285d],
        ChestedHorse: 0b,
        Fire: -1s,
        ArmorItems: [
          {},
          {},
          {},
          {}
        ],
        Temper: 15,
        CanPickUpLoot: 0b,
        HurtTime: 0s,
        Strength: 3
      },
      blockPos: [2, 1, 3],
      pos: [2.099898371531765d, 1.0d, 3.4887765942828537d]
    },
    {
      nbt: {
        Motion: [0.0d, 0.0d, 0.0d],
        Facing: 3b,
        Invulnerable: 0b,
        Air: 300s,
        OnGround: 0b,
        Dimension: 0,
        PortalCooldown: 0,
        Rotation: [270.0f, 0.0f],
        FallDistance: 0.0f,
        Motive: "minecraft:sunset",
        Pos: [-217.96875d, 58.5d, 88.0d],
        Fire: -1s,
        TileY: 58,
        id: "minecraft:painting",
        TileX: -218,
        UUID: [I; -582023314, -1759820995, -1453418377, 1109698267],
        TileZ: 88
      },
      blockPos: [1, 2, 6],
      pos: [1.03125d, 2.5d, 6.0d]
    }
  ],
  blocks: [
    {
      pos: [0, 0, 0],
      state: 0
    },
    {
      pos: [1, 0, 0],
      state: 0
    },
    {
      pos: [2, 0, 0],
      state: 0
    },
    {
      pos: [3, 0, 0],
      state: 0
    },
    {
      pos: [4, 0, 0],
      state: 0
    },
    {
      pos: [5, 0, 0],
      state: 0
    },
    {
      pos: [6, 0, 0],
      state: 0
    },
    {
      pos: [7, 0, 0],
      state: 0
    },
    {
      pos: [0, 1, 0],
      state: 1
    },
    {
      pos: [1, 1, 0],
      state: 1
    },
    {
      pos: [2, 1, 0],
      state: 1
    },
    {
      pos: [3, 1, 0],
      state: 1
    },
    {
      pos: [4, 1, 0],
      state: 1
    },
    {
      pos: [5, 1, 0],
      state: 1
    },
    {
      pos: [6, 1, 0],
      state: 1
    },
    {
      pos: [0, 2, 0],
      state: 1
    },
    {
      pos: [1, 2, 0],
      state: 1
    },
    {
      pos: [2, 2, 0],
      state: 1
    },
    {
      pos: [3, 2, 0],
      state: 1
    },
    {
      pos: [4, 2, 0],
      state: 1
    },
    {
      pos: [5, 2, 0],
      state: 1
    },
    {
      pos: [6, 2, 0],
      state: 1
    },
    {
      pos: [0, 3, 0],
      state: 1
    },
    {
      pos: [1, 3, 0],
      state: 1
    },
    {
      pos: [2, 3, 0],
      state: 1
    },
    {
      pos: [3, 3, 0],
      state: 1
    },
    {
      pos: [4, 3, 0],
      state: 1
    },
    {
      pos: [5, 3, 0],
      state: 1
    },
    {
      pos: [6, 3, 0],
      state: 1
    },
    {
      pos: [0, 4, 0],
      state: 1
    },
    {
      pos: [1, 4, 0],
      state: 1
    },
    {
      pos: [2, 4, 0],
      state: 1
    },
    {
      pos: [3, 4, 0],
      state: 1
    },
    {
      pos: [4, 4, 0],
      state: 1
    },
    {
      pos: [5, 4, 0],
      state: 1
    },
    {
      pos: [6, 4, 0],
      state: 1
    },
    {
      pos: [0, 0, 1],
      state: 0
    },
    {
      pos: [1, 0, 1],
      state: 2
    },
    {
      pos: [2, 0, 1],
      state: 2
    },
    {
      pos: [3, 0, 1],
      state: 2
    },
    {
      pos: [4, 0, 1],
      state: 2
    },
    {
      pos: [5, 0, 1],
      state: 2
    },
    {
      pos: [6, 0, 1],
      state: 0
    },
    {
      pos: [7, 0, 1],
      state: 0
    },
    {
      pos: [0, 1, 1],
      state: 1
    },
    {
      pos: [6, 1, 1],
      state: 1
    },
    {
      pos: [0, 2, 1],
      state: 1
    },
    {
      pos: [6, 2, 1],
      state: 1
    },
    {
      pos: [0, 3, 1],
      state: 1
    },
    {
      pos: [6, 3, 1],
      state: 1
    },
    {
      pos: [0, 4, 1],
      state: 1
    },
    {
      pos: [1, 4, 1],
      state: 2
    },
    {
      pos: [2, 4, 1],
      state: 2
    },
    {
      pos: [3, 4, 1],
      state: 2
    },
    {
      pos: [4, 4, 1],
      state: 2
    },
    {
      pos: [5, 4, 1],
      state: 2
    },
    {
      pos: [6, 4, 1],
      state: 1
    },
    {
      pos: [0, 0, 2],
      state: 0
    },
    {
      pos: [1, 0, 2],
      state: 0
    },
    {
      pos: [2, 0, 2],
      state: 3
    },
    {
      pos: [3, 0, 2],
      state: 3
    },
    {
      pos: [4, 0, 2],
      state: 3
    },
    {
      pos: [5, 0, 2],
      state: 3
    },
    {
      pos: [6, 0, 2],
      state: 0
    },
    {
      pos: [7, 0, 2],
      state: 0
    },
    {
      pos: [0, 1, 2],
      state: 0
    },
    {
      pos: [1, 1, 2],
      state: 0
    },
    {
      pos: [2, 1, 2],
      state: 0
    },
    {
      pos: [3, 1, 2],
      state: 0
    },
    {
      pos: [4, 1, 2],
      state: 0
    },
    {
      pos: [5, 1, 2],
      state: 0
    },
    {
      pos: [6, 1, 2],
      state: 0
    },
    {
      pos: [7, 1, 2],
      state: 0
    },
    {
      pos: [0, 2, 2],
      state: 0
    },
    {
      pos: [1, 2, 2],
      state: 0
    },
    {
      pos: [5, 2, 2],
      state: 0
    },
    {
      pos: [6, 2, 2],
      state: 0
    },
    {
      pos: [7, 2, 2],
      state: 0
    },
    {
      pos: [0, 3, 2],
      state: 0
    },
    {
      pos: [1, 3, 2],
      state: 0
    },
    {
      pos: [2, 3, 2],
      state: 0
    },
    {
      pos: [3, 3, 2],
      state: 0
    },
    {
      pos: [4, 3, 2],
      state: 0
    },
    {
      pos: [5, 3, 2],
      state: 0
    },
    {
      pos: [6, 3, 2],
      state: 0
    },
    {
      pos: [7, 3, 2],
      state: 0
    },
    {
      pos: [0, 4, 2],
      state: 0
    },
    {
      pos: [1, 4, 2],
      state: 0
    },
    {
      pos: [2, 4, 2],
      state: 0
    },
    {
      pos: [3, 4, 2],
      state: 0
    },
    {
      pos: [4, 4, 2],
      state: 0
    },
    {
      pos: [5, 4, 2],
      state: 0
    },
    {
      pos: [6, 4, 2],
      state: 0
    },
    {
      pos: [7, 4, 2],
      state: 0
    },
    {
      pos: [0, 0, 3],
      state: 0
    },
    {
      pos: [1, 0, 3],
      state: 0
    },
    {
      pos: [2, 0, 3],
      state: 0
    },
    {
      pos: [3, 0, 3],
      state: 0
    },
    {
      pos: [4, 0, 3],
      state: 0
    },
    {
      pos: [5, 0, 3],
      state: 0
    },
    {
      pos: [6, 0, 3],
      state: 0
    },
    {
      pos: [7, 0, 3],
      state: 0
    },
    {
      pos: [0, 1, 3],
      state: 0
    },
    {
      pos: [6, 1, 3],
      state: 0
    },
    {
      pos: [7, 1, 3],
      state: 0
    },
    {
      pos: [0, 2, 3],
      state: 0
    },
    {
      pos: [6, 2, 3],
      state: 0
    },
    {
      pos: [7, 2, 3],
      state: 0
    },
    {
      pos: [0, 3, 3],
      state: 0
    },
    {
      pos: [6, 3, 3],
      state: 0
    },
    {
      pos: [7, 3, 3],
      state: 0
    },
    {
      pos: [0, 4, 3],
      state: 0
    },
    {
      pos: [1, 4, 3],
      state: 0
    },
    {
      pos: [2, 4, 3],
      state: 0
    },
    {
      pos: [3, 4, 3],
      state: 0
    },
    {
      pos: [4, 4, 3],
      state: 0
    },
    {
      pos: [5, 4, 3],
      state: 0
    },
    {
      pos: [6, 4, 3],
      state: 0
    },
    {
      pos: [7, 4, 3],
      state: 0
    },
    {
      pos: [0, 0, 4],
      state: 0
    },
    {
      pos: [1, 0, 4],
      state: 0
    },
    {
      pos: [2, 0, 4],
      state: 0
    },
    {
      pos: [3, 0, 4],
      state: 0
    },
    {
      pos: [4, 0, 4],
      state: 0
    },
    {
      pos: [5, 0, 4],
      state: 0
    },
    {
      pos: [6, 0, 4],
      state: 0
    },
    {
      pos: [7, 0, 4],
      state: 0
    },
    {
      pos: [0, 1, 4],
      state: 0
    },
    {
      pos: [6, 1, 4],
      state: 4
    },
    {
      pos: [7, 1, 4],
      state: 0
    },
    {
      pos: [0, 2, 4],
      state: 0
    },
    {
      pos: [6, 2, 4],
      state: 4
    },
    {
      pos: [7, 2, 4],
      state: 0
    },
    {
      pos: [0, 3, 4],
      state: 0
    },
    {
      pos: [6, 3, 4],
      state: 4
    },
    {
      pos: [7, 3, 4],
      state: 0
    },
    {
      pos: [0, 4, 4],
      state: 0
    },
    {
      pos: [1, 4, 4],
      state: 0
    },
    {
      pos: [2, 4, 4],
      state: 0
    },
    {
      pos: [3, 4, 4],
      state: 0
    },
    {
      pos: [4, 4, 4],
      state: 0
    },
    {
      pos: [5, 4, 4],
      state: 0
    },
    {
      pos: [6, 4, 4],
      state: 0
    },
    {
      pos: [7, 4, 4],
      state: 0
    },
    {
      pos: [0, 0, 5],
      state: 0
    },
    {
      pos: [1, 0, 5],
      state: 0
    },
    {
      pos: [2, 0, 5],
      state: 0
    },
    {
      pos: [3, 0, 5],
      state: 0
    },
    {
      pos: [4, 0, 5],
      state: 0
    },
    {
      pos: [5, 0, 5],
      state: 0
    },
    {
      pos: [6, 0, 5],
      state: 4
    },
    {
      pos: [7, 0, 5],
      state: 0
    },
    {
      pos: [0, 1, 5],
      state: 0
    },
    {
      pos: [7, 1, 5],
      state: 0
    },
    {
      pos: [0, 2, 5],
      state: 2
    },
    {
      pos: [7, 2, 5],
      state: 0
    },
    {
      pos: [0, 3, 5],
      state: 0
    },
    {
      pos: [7, 3, 5],
      state: 0
    },
    {
      pos: [0, 4, 5],
      state: 0
    },
    {
      pos: [1, 4, 5],
      state: 0
    },
    {
      pos: [2, 4, 5],
      state: 0
    },
    {
      pos: [3, 4, 5],
      state: 0
    },
    {
      pos: [4, 4, 5],
      state: 0
    },
    {
      pos: [5, 4, 5],
      state: 0
    },
    {
      pos: [6, 4, 5],
      state: 4
    },
    {
      pos: [7, 4, 5],
      state: 0
    },
    {
      pos: [0, 0, 6],
      state: 0
    },
    {
      pos: [1, 0, 6],
      state: 0
    },
    {
      pos: [2, 0, 6],
      state: 0
    },
    {
      pos: [3, 0, 6],
      state: 0
    },
    {
      pos: [4, 0, 6],
      state: 0
    },
    {
      pos: [5, 0, 6],
      state: 0
    },
    {
      pos: [6, 0, 6],
      state: 4
    },
    {
      pos: [7, 0, 6],
      state: 0
    },
    {
      pos: [0, 1, 6],
      state: 0
    },
    {
      pos: [7, 1, 6],
      state: 0
    },
    {
      pos: [0, 2, 6],
      state: 2
    },
    {
      pos: [7, 2, 6],
      state: 0
    },
    {
      pos: [0, 3, 6],
      state: 0
    },
    {
      pos: [7, 3, 6],
      state: 0
    },
    {
      pos: [0, 4, 6],
      state: 0
    },
    {
      pos: [1, 4, 6],
      state: 0
    },
    {
      pos: [2, 4, 6],
      state: 0
    },
    {
      pos: [3, 4, 6],
      state: 0
    },
    {
      pos: [4, 4, 6],
      state: 0
    },
    {
      pos: [5, 4, 6],
      state: 0
    },
    {
      pos: [6, 4, 6],
      state: 4
    },
    {
      pos: [7, 4, 6],
      state: 0
    },
    {
      pos: [0, 0, 7],
      state: 0
    },
    {
      pos: [1, 0, 7],
      state: 0
    },
    {
      pos: [2, 0, 7],
      state: 0
    },
    {
      pos: [3, 0, 7],
      state: 0
    },
    {
      pos: [4, 0, 7],
      state: 0
    },
    {
      pos: [5, 0, 7],
      state: 0
    },
    {
      pos: [6, 0, 7],
      state: 0
    },
    {
      pos: [7, 0, 7],
      state: 0
    },
    {
      pos: [0, 1, 7],
      state: 0
    },
    {
      pos: [6, 1, 7],
      state: 4
    },
    {
      pos: [7, 1, 7],
      state: 0
    },
    {
      pos: [0, 2, 7],
      state: 0
    },
    {
      pos: [6, 2, 7],
      state: 4
    },
    {
      pos: [7, 2, 7],
      state: 0
    },
    {
      pos: [0, 3, 7],
      state: 0
    },
    {
      pos: [6, 3, 7],
      state: 4
    },
    {
      pos: [7, 3, 7],
      state: 0
    },
    {
      pos: [0, 4, 7],
      state: 0
    },
    {
      pos: [1, 4, 7],
      state: 0
    },
    {
      pos: [2, 4, 7],
      state: 0
    },
    {
      pos: [3, 4, 7],
      state: 0
    },
    {
      pos: [4, 4, 7],
      state: 0
    },
    {
      pos: [5, 4, 7],
      state: 0
    },
    {
      pos: [6, 4, 7],
      state: 0
    },
    {
      pos: [7, 4, 7],
      state: 0
    },
    {
      pos: [0, 0, 8],
      state: 0
    },
    {
      pos: [1, 0, 8],
      state: 0
    },
    {
      pos: [2, 0, 8],
      state: 0
    },
    {
      pos: [3, 0, 8],
      state: 0
    },
    {
      pos: [4, 0, 8],
      state: 0
    },
    {
      pos: [5, 0, 8],
      state: 0
    },
    {
      pos: [6, 0, 8],
      state: 0
    },
    {
      pos: [7, 0, 8],
      state: 0
    },
    {
      pos: [0, 1, 8],
      state: 0
    },
    {
      pos: [6, 1, 8],
      state: 0
    },
    {
      pos: [7, 1, 8],
      state: 0
    },
    {
      pos: [0, 2, 8],
      state: 0
    },
    {
      pos: [6, 2, 8],
      state: 0
    },
    {
      pos: [7, 2, 8],
      state: 0
    },
    {
      pos: [0, 3, 8],
      state: 0
    },
    {
      pos: [6, 3, 8],
      state: 0
    },
    {
      pos: [7, 3, 8],
      state: 0
    },
    {
      pos: [0, 4, 8],
      state: 0
    },
    {
      pos: [1, 4, 8],
      state: 0
    },
    {
      pos: [2, 4, 8],
      state: 0
    },
    {
      pos: [3, 4, 8],
      state: 0
    },
    {
      pos: [4, 4, 8],
      state: 0
    },
    {
      pos: [5, 4, 8],
      state: 0
    },
    {
      pos: [6, 4, 8],
      state: 0
    },
    {
      pos: [7, 4, 8],
      state: 0
    },
    {
      pos: [0, 0, 9],
      state: 0
    },
    {
      pos: [1, 0, 9],
      state: 0
    },
    {
      pos: [2, 0, 9],
      state: 0
    },
    {
      pos: [3, 0, 9],
      state: 0
    },
    {
      pos: [4, 0, 9],
      state: 0
    },
    {
      pos: [5, 0, 9],
      state: 0
    },
    {
      pos: [6, 0, 9],
      state: 0
    },
    {
      pos: [7, 0, 9],
      state: 0
    },
    {
      pos: [0, 1, 9],
      state: 0
    },
    {
      pos: [1, 1, 9],
      state: 0
    },
    {
      pos: [2, 1, 9],
      state: 0
    },
    {
      pos: [3, 1, 9],
      state: 0
    },
    {
      pos: [4, 1, 9],
      state: 0
    },
    {
      pos: [5, 1, 9],
      state: 0
    },
    {
      pos: [6, 1, 9],
      state: 0
    },
    {
      pos: [7, 1, 9],
      state: 0
    },
    {
      pos: [0, 2, 9],
      state: 0
    },
    {
      pos: [1, 2, 9],
      state: 0
    },
    {
      pos: [2, 2, 9],
      state: 0
    },
    {
      pos: [3, 2, 9],
      state: 0
    },
    {
      pos: [4, 2, 9],
      state: 0
    },
    {
      pos: [5, 2, 9],
      state: 0
    },
    {
      pos: [6, 2, 9],
      state: 0
    },
    {
      pos: [7, 2, 9],
      state: 0
    },
    {
      pos: [0, 3, 9],
      state: 0
    },
    {
      pos: [1, 3, 9],
      state: 0
    },
    {
      pos: [2, 3, 9],
      state: 0
    },
    {
      pos: [3, 3, 9],
      state: 0
    },
    {
      pos: [4, 3, 9],
      state: 0
    },
    {
      pos: [5, 3, 9],
      state: 0
    },
    {
      pos: [6, 3, 9],
      state: 0
    },
    {
      pos: [7, 3, 9],
      state: 0
    },
    {
      pos: [0, 4, 9],
      state: 0
    },
    {
      pos: [1, 4, 9],
      state: 0
    },
    {
      pos: [2, 4, 9],
      state: 0
    },
    {
      pos: [3, 4, 9],
      state: 0
    },
    {
      pos: [4, 4, 9],
      state: 0
    },
    {
      pos: [5, 4, 9],
      state: 0
    },
    {
      pos: [6, 4, 9],
      state: 0
    },
    {
      pos: [7, 4, 9],
      state: 0
    },
    {
      nbt: {
        Items: [
          {
            Slot: 13b,
            id: "minecraft:written_book",
            Count: 1b,
            tag: {
              pages: ["{\"text\":\"Nothing to solve\"}"],
              title: "A Book",
              author: "Developer",
              resolved: 1b
            }
          }
        ],
        id: "minecraft:chest"
      },
      pos: [7, 1, 0],
      state: 5
    },
    {
      nbt: {
        Color: "light_blue",
        Text4: "{\"text\":\"\"}",
        Text3: "{\"text\":\"\"}",
        Text2: "{\"text\":\"ENJOY!\"}",
        id: "minecraft:sign",
        Text1: "{\"text\":\"\"}"
      },
      pos: [2, 2, 8],
      state: 6
    },
    {
      nbt: {
        Color: "red",
        Text4: "{\"text\":\"\"}",
        Text3: "{\"text\":\"\"}",
        Text2: "{\"text\":\"RELAX!\"}",
        id: "minecraft:sign",
        Text1: "{\"text\":\"\"}"
      },
      pos: [4, 2, 8],
      state: 7
    },
    {
      pos: [7, 2, 0],
      state: 8
    },
    {
      pos: [7, 3, 0],
      state: 8
    },
    {
      pos: [7, 4, 0],
      state: 8
    },
    {
      pos: [1, 1, 1],
      state: 8
    },
    {
      pos: [2, 1, 1],
      state: 8
    },
    {
      pos: [3, 1, 1],
      state: 8
    },
    {
      pos: [4, 1, 1],
      state: 8
    },
    {
      pos: [5, 1, 1],
      state: 8
    },
    {
      pos: [7, 1, 1],
      state: 8
    },
    {
      pos: [1, 2, 1],
      state: 8
    },
    {
      pos: [2, 2, 1],
      state: 8
    },
    {
      pos: [3, 2, 1],
      state: 8
    },
    {
      pos: [4, 2, 1],
      state: 8
    },
    {
      pos: [5, 2, 1],
      state: 8
    },
    {
      pos: [7, 2, 1],
      state: 8
    },
    {
      pos: [1, 3, 1],
      state: 8
    },
    {
      pos: [2, 3, 1],
      state: 8
    },
    {
      pos: [3, 3, 1],
      state: 8
    },
    {
      pos: [4, 3, 1],
      state: 8
    },
    {
      pos: [5, 3, 1],
      state: 8
    },
    {
      pos: [7, 3, 1],
      state: 8
    },
    {
      pos: [7, 4, 1],
      state: 8
    },
    {
      pos: [2, 2, 2],
      state: 9
    },
    {
      pos: [3, 2, 2],
      state: 9
    },
    {
      pos: [4, 2, 2],
      state: 9
    },
    {
      pos: [1, 1, 3],
      state: 8
    },
    {
      pos: [2, 1, 3],
      state: 8
    },
    {
      pos: [3, 1, 3],
      state: 10
    },
    {
      pos: [4, 1, 3],
      state: 11
    },
    {
      pos: [5, 1, 3],
      state: 11
    },
    {
      pos: [1, 2, 3],
      state: 8
    },
    {
      pos: [2, 2, 3],
      state: 8
    },
    {
      pos: [3, 2, 3],
      state: 8
    },
    {
      pos: [4, 2, 3],
      state: 8
    },
    {
      pos: [5, 2, 3],
      state: 8
    },
    {
      pos: [1, 3, 3],
      state: 8
    },
    {
      pos: [2, 3, 3],
      state: 8
    },
    {
      pos: [3, 3, 3],
      state: 8
    },
    {
      pos: [4, 3, 3],
      state: 8
    },
    {
      pos: [5, 3, 3],
      state: 8
    },
    {
      pos: [1, 1, 4],
      state: 12
    },
    {
      pos: [2, 1, 4],
      state: 12
    },
    {
      pos: [3, 1, 4],
      state: 13
    },
    {
      pos: [4, 1, 4],
      state: 11
    },
    {
      pos: [5, 1, 4],
      state: 11
    },
    {
      pos: [1, 2, 4],
      state: 8
    },
    {
      pos: [2, 2, 4],
      state: 8
    },
    {
      pos: [3, 2, 4],
      state: 8
    },
    {
      pos: [4, 2, 4],
      state: 8
    },
    {
      pos: [5, 2, 4],
      state: 14
    },
    {
      pos: [1, 3, 4],
      state: 8
    },
    {
      pos: [2, 3, 4],
      state: 8
    },
    {
      pos: [3, 3, 4],
      state: 8
    },
    {
      pos: [4, 3, 4],
      state: 8
    },
    {
      pos: [5, 3, 4],
      state: 8
    },
    {
      pos: [1, 1, 5],
      state: 11
    },
    {
      pos: [2, 1, 5],
      state: 11
    },
    {
      pos: [3, 1, 5],
      state: 11
    },
    {
      pos: [4, 1, 5],
      state: 11
    },
    {
      pos: [5, 1, 5],
      state: 11
    },
    {
      pos: [6, 1, 5],
      state: 15
    },
    {
      pos: [1, 2, 5],
      state: 8
    },
    {
      pos: [2, 2, 5],
      state: 8
    },
    {
      pos: [3, 2, 5],
      state: 8
    },
    {
      pos: [4, 2, 5],
      state: 8
    },
    {
      pos: [5, 2, 5],
      state: 8
    },
    {
      pos: [6, 2, 5],
      state: 15
    },
    {
      pos: [1, 3, 5],
      state: 8
    },
    {
      pos: [2, 3, 5],
      state: 8
    },
    {
      pos: [3, 3, 5],
      state: 8
    },
    {
      pos: [4, 3, 5],
      state: 8
    },
    {
      pos: [5, 3, 5],
      state: 8
    },
    {
      pos: [6, 3, 5],
      state: 15
    },
    {
      pos: [1, 1, 6],
      state: 11
    },
    {
      pos: [2, 1, 6],
      state: 11
    },
    {
      pos: [3, 1, 6],
      state: 11
    },
    {
      pos: [4, 1, 6],
      state: 11
    },
    {
      pos: [5, 1, 6],
      state: 11
    },
    {
      pos: [6, 1, 6],
      state: 15
    },
    {
      pos: [1, 2, 6],
      state: 8
    },
    {
      pos: [2, 2, 6],
      state: 8
    },
    {
      pos: [3, 2, 6],
      state: 8
    },
    {
      pos: [4, 2, 6],
      state: 8
    },
    {
      pos: [5, 2, 6],
      state: 8
    },
    {
      pos: [6, 2, 6],
      state: 15
    },
    {
      pos: [1, 3, 6],
      state: 8
    },
    {
      pos: [2, 3, 6],
      state: 8
    },
    {
      pos: [3, 3, 6],
      state: 8
    },
    {
      pos: [4, 3, 6],
      state: 8
    },
    {
      pos: [5, 3, 6],
      state: 8
    },
    {
      pos: [6, 3, 6],
      state: 15
    },
    {
      pos: [1, 1, 7],
      state: 11
    },
    {
      pos: [2, 1, 7],
      state: 11
    },
    {
      pos: [3, 1, 7],
      state: 11
    },
    {
      pos: [4, 1, 7],
      state: 11
    },
    {
      pos: [5, 1, 7],
      state: 11
    },
    {
      pos: [1, 2, 7],
      state: 8
    },
    {
      pos: [2, 2, 7],
      state: 8
    },
    {
      pos: [3, 2, 7],
      state: 8
    },
    {
      pos: [4, 2, 7],
      state: 8
    },
    {
      pos: [5, 2, 7],
      state: 14
    },
    {
      pos: [1, 3, 7],
      state: 8
    },
    {
      pos: [2, 3, 7],
      state: 8
    },
    {
      pos: [3, 3, 7],
      state: 8
    },
    {
      pos: [4, 3, 7],
      state: 8
    },
    {
      pos: [5, 3, 7],
      state: 8
    },
    {
      pos: [1, 1, 8],
      state: 11
    },
    {
      pos: [2, 1, 8],
      state: 11
    },
    {
      pos: [3, 1, 8],
      state: 11
    },
    {
      pos: [4, 1, 8],
      state: 11
    },
    {
      pos: [5, 1, 8],
      state: 11
    },
    {
      pos: [1, 2, 8],
      state: 8
    },
    {
      pos: [3, 2, 8],
      state: 8
    },
    {
      pos: [5, 2, 8],
      state: 8
    },
    {
      pos: [1, 3, 8],
      state: 8
    },
    {
      pos: [2, 3, 8],
      state: 8
    },
    {
      pos: [3, 3, 8],
      state: 8
    },
    {
      pos: [4, 3, 8],
      state: 8
    },
    {
      pos: [5, 3, 8],
      state: 8
    }
  ],
  palette: [
    {
      Name: "minecraft:smooth_quartz"
    },
    {
      Name: "minecraft:light_blue_concrete"
    },
    {
      Name: "minecraft:glowstone"
    },
    {
      Name: "minecraft:bedrock"
    },
    {
      Name: "minecraft:obsidian"
    },
    {
      Properties: {
        waterlogged: "false",
        facing: "south",
        type: "single"
      },
      Name: "minecraft:chest"
    },
    {
      Properties: {
        waterlogged: "false",
        facing: "north"
      },
      Name: "minecraft:crimson_wall_sign"
    },
    {
      Properties: {
        waterlogged: "false",
        facing: "north"
      },
      Name: "minecraft:warped_wall_sign"
    },
    {
      Name: "minecraft:air"
    },
    {
      Properties: {
        east: "true",
        waterlogged: "false",
        south: "false",
        north: "false",
        west: "true"
      },
      Name: "minecraft:glass_pane"
    },
    {
      Properties: {
        east: "false",
        waterlogged: "false",
        south: "true",
        north: "true",
        west: "false"
      },
      Name: "minecraft:birch_fence"
    },
    {
      Name: "minecraft:white_carpet"
    },
    {
      Properties: {
        east: "true",
        waterlogged: "false",
        south: "false",
        north: "false",
        west: "true"
      },
      Name: "minecraft:birch_fence"
    },
    {
      Properties: {
        east: "false",
        waterlogged: "false",
        south: "false",
        north: "true",
        west: "true"
      },
      Name: "minecraft:birch_fence"
    },
    {
      Properties: {
        facing: "west"
      },
      Name: "minecraft:wall_torch"
    },
    {
      Properties: {
        axis: "z"
      },
      Name: "minecraft:nether_portal"
    }
  ],
  DataVersion: 2519
}