{
  size: [11, 3, 6],
  entities: [],
  blocks: [
    {
      pos: [2, 0, 0],
      state: 0
    },
    {
      pos: [7, 0, 0],
      state: 0
    },
    {
      pos: [8, 0, 0],
      state: 0
    },
    {
      pos: [1, 0, 1],
      state: 0
    },
    {
      pos: [5, 0, 1],
      state: 0
    },
    {
      pos: [8, 0, 1],
      state: 0
    },
    {
      pos: [10, 0, 1],
      state: 0
    },
    {
      pos: [0, 0, 2],
      state: 0
    },
    {
      pos: [2, 0, 2],
      state: 0
    },
    {
      pos: [4, 0, 2],
      state: 0
    },
    {
      pos: [7, 0, 2],
      state: 0
    },
    {
      pos: [8, 0, 2],
      state: 1
    },
    {
      pos: [9, 0, 2],
      state: 0
    },
    {
      pos: [8, 1, 2],
      state: 2
    },
    {
      pos: [8, 0, 3],
      state: 0
    },
    {
      pos: [0, 0, 4],
      state: 0
    },
    {
      pos: [2, 0, 4],
      state: 0
    },
    {
      pos: [5, 0, 4],
      state: 0
    },
    {
      pos: [7, 0, 4],
      state: 0
    },
    {
      pos: [0, 0, 5],
      state: 0
    },
    {
      pos: [1, 0, 5],
      state: 0
    },
    {
      pos: [3, 0, 5],
      state: 0
    },
    {
      pos: [5, 0, 5],
      state: 0
    },
    {
      pos: [6, 0, 5],
      state: 0
    },
    {
      pos: [8, 0, 5],
      state: 0
    },
    {
      pos: [10, 0, 5],
      state: 0
    },
    {
      nbt: {
        id: "minecraft:bell"
      },
      pos: [8, 2, 2],
      state: 3
    },
    {
      pos: [0, 0, 0],
      state: 4
    },
    {
      pos: [1, 0, 0],
      state: 4
    },
    {
      pos: [3, 0, 0],
      state: 4
    },
    {
      pos: [4, 0, 0],
      state: 4
    },
    {
      pos: [5, 0, 0],
      state: 4
    },
    {
      pos: [6, 0, 0],
      state: 4
    },
    {
      pos: [9, 0, 0],
      state: 4
    },
    {
      pos: [10, 0, 0],
      state: 4
    },
    {
      pos: [0, 1, 0],
      state: 5
    },
    {
      pos: [1, 1, 0],
      state: 5
    },
    {
      pos: [2, 1, 0],
      state: 5
    },
    {
      pos: [3, 1, 0],
      state: 5
    },
    {
      pos: [4, 1, 0],
      state: 5
    },
    {
      pos: [5, 1, 0],
      state: 5
    },
    {
      pos: [6, 1, 0],
      state: 5
    },
    {
      pos: [7, 1, 0],
      state: 5
    },
    {
      pos: [8, 1, 0],
      state: 5
    },
    {
      pos: [9, 1, 0],
      state: 5
    },
    {
      pos: [10, 1, 0],
      state: 5
    },
    {
      pos: [0, 2, 0],
      state: 5
    },
    {
      pos: [1, 2, 0],
      state: 5
    },
    {
      pos: [2, 2, 0],
      state: 5
    },
    {
      pos: [3, 2, 0],
      state: 5
    },
    {
      pos: [4, 2, 0],
      state: 5
    },
    {
      pos: [5, 2, 0],
      state: 5
    },
    {
      pos: [6, 2, 0],
      state: 5
    },
    {
      pos: [7, 2, 0],
      state: 5
    },
    {
      pos: [8, 2, 0],
      state: 5
    },
    {
      pos: [9, 2, 0],
      state: 5
    },
    {
      pos: [10, 2, 0],
      state: 5
    },
    {
      pos: [0, 0, 1],
      state: 4
    },
    {
      pos: [2, 0, 1],
      state: 4
    },
    {
      pos: [3, 0, 1],
      state: 4
    },
    {
      pos: [4, 0, 1],
      state: 4
    },
    {
      pos: [6, 0, 1],
      state: 4
    },
    {
      pos: [7, 0, 1],
      state: 4
    },
    {
      pos: [9, 0, 1],
      state: 4
    },
    {
      pos: [0, 1, 1],
      state: 5
    },
    {
      pos: [1, 1, 1],
      state: 5
    },
    {
      pos: [2, 1, 1],
      state: 5
    },
    {
      pos: [3, 1, 1],
      state: 5
    },
    {
      pos: [4, 1, 1],
      state: 5
    },
    {
      pos: [5, 1, 1],
      state: 5
    },
    {
      pos: [6, 1, 1],
      state: 5
    },
    {
      pos: [7, 1, 1],
      state: 5
    },
    {
      pos: [8, 1, 1],
      state: 6
    },
    {
      pos: [9, 1, 1],
      state: 5
    },
    {
      pos: [10, 1, 1],
      state: 5
    },
    {
      pos: [0, 2, 1],
      state: 5
    },
    {
      pos: [1, 2, 1],
      state: 5
    },
    {
      pos: [2, 2, 1],
      state: 5
    },
    {
      pos: [3, 2, 1],
      state: 5
    },
    {
      pos: [4, 2, 1],
      state: 5
    },
    {
      pos: [5, 2, 1],
      state: 5
    },
    {
      pos: [6, 2, 1],
      state: 5
    },
    {
      pos: [7, 2, 1],
      state: 5
    },
    {
      pos: [8, 2, 1],
      state: 5
    },
    {
      pos: [9, 2, 1],
      state: 5
    },
    {
      pos: [10, 2, 1],
      state: 5
    },
    {
      pos: [1, 0, 2],
      state: 4
    },
    {
      pos: [3, 0, 2],
      state: 4
    },
    {
      pos: [5, 0, 2],
      state: 4
    },
    {
      pos: [6, 0, 2],
      state: 4
    },
    {
      pos: [10, 0, 2],
      state: 4
    },
    {
      pos: [0, 1, 2],
      state: 5
    },
    {
      pos: [1, 1, 2],
      state: 5
    },
    {
      pos: [2, 1, 2],
      state: 5
    },
    {
      pos: [3, 1, 2],
      state: 5
    },
    {
      pos: [4, 1, 2],
      state: 5
    },
    {
      pos: [5, 1, 2],
      state: 5
    },
    {
      pos: [6, 1, 2],
      state: 5
    },
    {
      pos: [7, 1, 2],
      state: 7
    },
    {
      pos: [9, 1, 2],
      state: 8
    },
    {
      pos: [10, 1, 2],
      state: 5
    },
    {
      pos: [0, 2, 2],
      state: 5
    },
    {
      pos: [1, 2, 2],
      state: 5
    },
    {
      pos: [2, 2, 2],
      state: 5
    },
    {
      pos: [3, 2, 2],
      state: 5
    },
    {
      pos: [4, 2, 2],
      state: 5
    },
    {
      pos: [5, 2, 2],
      state: 5
    },
    {
      pos: [6, 2, 2],
      state: 5
    },
    {
      pos: [7, 2, 2],
      state: 5
    },
    {
      pos: [9, 2, 2],
      state: 5
    },
    {
      pos: [10, 2, 2],
      state: 5
    },
    {
      pos: [0, 0, 3],
      state: 4
    },
    {
      pos: [1, 0, 3],
      state: 4
    },
    {
      pos: [2, 0, 3],
      state: 4
    },
    {
      pos: [3, 0, 3],
      state: 4
    },
    {
      pos: [4, 0, 3],
      state: 4
    },
    {
      pos: [5, 0, 3],
      state: 4
    },
    {
      pos: [6, 0, 3],
      state: 4
    },
    {
      pos: [7, 0, 3],
      state: 4
    },
    {
      pos: [9, 0, 3],
      state: 4
    },
    {
      pos: [10, 0, 3],
      state: 4
    },
    {
      pos: [0, 1, 3],
      state: 5
    },
    {
      pos: [1, 1, 3],
      state: 5
    },
    {
      pos: [2, 1, 3],
      state: 5
    },
    {
      pos: [3, 1, 3],
      state: 5
    },
    {
      pos: [4, 1, 3],
      state: 5
    },
    {
      pos: [5, 1, 3],
      state: 5
    },
    {
      pos: [6, 1, 3],
      state: 5
    },
    {
      pos: [7, 1, 3],
      state: 5
    },
    {
      pos: [8, 1, 3],
      state: 9
    },
    {
      pos: [9, 1, 3],
      state: 5
    },
    {
      pos: [10, 1, 3],
      state: 5
    },
    {
      pos: [0, 2, 3],
      state: 5
    },
    {
      pos: [1, 2, 3],
      state: 5
    },
    {
      pos: [2, 2, 3],
      state: 5
    },
    {
      pos: [3, 2, 3],
      state: 5
    },
    {
      pos: [4, 2, 3],
      state: 5
    },
    {
      pos: [5, 2, 3],
      state: 5
    },
    {
      pos: [6, 2, 3],
      state: 5
    },
    {
      pos: [7, 2, 3],
      state: 5
    },
    {
      pos: [8, 2, 3],
      state: 5
    },
    {
      pos: [9, 2, 3],
      state: 5
    },
    {
      pos: [10, 2, 3],
      state: 5
    },
    {
      pos: [1, 0, 4],
      state: 4
    },
    {
      pos: [3, 0, 4],
      state: 4
    },
    {
      pos: [4, 0, 4],
      state: 4
    },
    {
      pos: [6, 0, 4],
      state: 4
    },
    {
      pos: [8, 0, 4],
      state: 4
    },
    {
      pos: [9, 0, 4],
      state: 4
    },
    {
      pos: [10, 0, 4],
      state: 4
    },
    {
      pos: [0, 1, 4],
      state: 5
    },
    {
      pos: [1, 1, 4],
      state: 5
    },
    {
      pos: [2, 1, 4],
      state: 5
    },
    {
      pos: [3, 1, 4],
      state: 5
    },
    {
      pos: [4, 1, 4],
      state: 5
    },
    {
      pos: [5, 1, 4],
      state: 5
    },
    {
      pos: [6, 1, 4],
      state: 5
    },
    {
      pos: [7, 1, 4],
      state: 5
    },
    {
      pos: [8, 1, 4],
      state: 5
    },
    {
      pos: [9, 1, 4],
      state: 5
    },
    {
      pos: [10, 1, 4],
      state: 5
    },
    {
      pos: [0, 2, 4],
      state: 5
    },
    {
      pos: [1, 2, 4],
      state: 5
    },
    {
      pos: [2, 2, 4],
      state: 5
    },
    {
      pos: [3, 2, 4],
      state: 5
    },
    {
      pos: [4, 2, 4],
      state: 5
    },
    {
      pos: [5, 2, 4],
      state: 5
    },
    {
      pos: [6, 2, 4],
      state: 5
    },
    {
      pos: [7, 2, 4],
      state: 5
    },
    {
      pos: [8, 2, 4],
      state: 5
    },
    {
      pos: [9, 2, 4],
      state: 5
    },
    {
      pos: [10, 2, 4],
      state: 5
    },
    {
      pos: [2, 0, 5],
      state: 4
    },
    {
      pos: [4, 0, 5],
      state: 4
    },
    {
      pos: [7, 0, 5],
      state: 4
    },
    {
      pos: [9, 0, 5],
      state: 4
    },
    {
      pos: [0, 1, 5],
      state: 5
    },
    {
      pos: [1, 1, 5],
      state: 5
    },
    {
      pos: [2, 1, 5],
      state: 5
    },
    {
      pos: [3, 1, 5],
      state: 5
    },
    {
      pos: [4, 1, 5],
      state: 5
    },
    {
      pos: [5, 1, 5],
      state: 5
    },
    {
      pos: [6, 1, 5],
      state: 5
    },
    {
      pos: [7, 1, 5],
      state: 5
    },
    {
      pos: [8, 1, 5],
      state: 5
    },
    {
      pos: [9, 1, 5],
      state: 5
    },
    {
      pos: [10, 1, 5],
      state: 5
    },
    {
      pos: [0, 2, 5],
      state: 5
    },
    {
      pos: [1, 2, 5],
      state: 5
    },
    {
      pos: [2, 2, 5],
      state: 5
    },
    {
      pos: [3, 2, 5],
      state: 5
    },
    {
      pos: [4, 2, 5],
      state: 5
    },
    {
      pos: [5, 2, 5],
      state: 5
    },
    {
      pos: [6, 2, 5],
      state: 5
    },
    {
      pos: [7, 2, 5],
      state: 5
    },
    {
      pos: [8, 2, 5],
      state: 5
    },
    {
      pos: [9, 2, 5],
      state: 5
    },
    {
      pos: [10, 2, 5],
      state: 5
    }
  ],
  palette: [
    {
      Properties: {
        snowy: "false"
      },
      Name: "minecraft:grass_block"
    },
    {
      Name: "minecraft:dirt"
    },
    {
      Name: "minecraft:spruce_planks"
    },
    {
      Properties: {
        face: "floor",
        facing: "north"
      },
      Name: "minecraft:bell"
    },
    {
      Name: "minecraft:grass_path"
    },
    {
      Name: "minecraft:air"
    },
    {
      Properties: {
        half: "bottom",
        waterlogged: "false",
        powered: "false",
        facing: "north",
        open: "true"
      },
      Name: "minecraft:spruce_trapdoor"
    },
    {
      Properties: {
        half: "bottom",
        waterlogged: "false",
        powered: "false",
        facing: "west",
        open: "true"
      },
      Name: "minecraft:spruce_trapdoor"
    },
    {
      Properties: {
        half: "bottom",
        waterlogged: "false",
        powered: "false",
        facing: "east",
        open: "true"
      },
      Name: "minecraft:spruce_trapdoor"
    },
    {
      Properties: {
        half: "bottom",
        waterlogged: "false",
        powered: "false",
        facing: "south",
        open: "true"
      },
      Name: "minecraft:spruce_trapdoor"
    }
  ],
  DataVersion: 1907
}