{
  size: [10, 8, 8],
  entities: [],
  blocks: [
    {
      pos: [0, 0, 0],
      state: 0
    },
    {
      pos: [0, 0, 1],
      state: 0
    },
    {
      pos: [0, 0, 6],
      state: 0
    },
    {
      pos: [0, 0, 7],
      state: 0
    },
    {
      pos: [1, 0, 0],
      state: 0
    },
    {
      pos: [1, 0, 1],
      state: 1
    },
    {
      pos: [1, 0, 2],
      state: 1
    },
    {
      pos: [1, 0, 3],
      state: 0
    },
    {
      pos: [1, 0, 4],
      state: 0
    },
    {
      pos: [1, 0, 5],
      state: 1
    },
    {
      pos: [1, 0, 6],
      state: 1
    },
    {
      pos: [1, 0, 7],
      state: 0
    },
    {
      pos: [2, 0, 0],
      state: 0
    },
    {
      pos: [2, 0, 1],
      state: 1
    },
    {
      pos: [2, 0, 2],
      state: 2
    },
    {
      pos: [2, 0, 3],
      state: 2
    },
    {
      pos: [2, 0, 4],
      state: 2
    },
    {
      pos: [2, 0, 5],
      state: 2
    },
    {
      pos: [2, 0, 6],
      state: 1
    },
    {
      pos: [2, 0, 7],
      state: 0
    },
    {
      pos: [3, 0, 1],
      state: 1
    },
    {
      pos: [3, 0, 2],
      state: 2
    },
    {
      pos: [3, 0, 3],
      state: 2
    },
    {
      pos: [3, 0, 4],
      state: 2
    },
    {
      pos: [3, 0, 5],
      state: 2
    },
    {
      pos: [3, 0, 6],
      state: 1
    },
    {
      pos: [4, 0, 1],
      state: 1
    },
    {
      pos: [4, 0, 2],
      state: 2
    },
    {
      pos: [4, 0, 3],
      state: 2
    },
    {
      pos: [4, 0, 4],
      state: 2
    },
    {
      pos: [4, 0, 5],
      state: 2
    },
    {
      pos: [4, 0, 6],
      state: 1
    },
    {
      pos: [5, 0, 1],
      state: 1
    },
    {
      pos: [5, 0, 2],
      state: 2
    },
    {
      pos: [5, 0, 3],
      state: 2
    },
    {
      pos: [5, 0, 4],
      state: 2
    },
    {
      pos: [5, 0, 5],
      state: 2
    },
    {
      pos: [5, 0, 6],
      state: 1
    },
    {
      pos: [6, 0, 1],
      state: 1
    },
    {
      pos: [6, 0, 2],
      state: 2
    },
    {
      pos: [6, 0, 3],
      state: 2
    },
    {
      pos: [6, 0, 4],
      state: 2
    },
    {
      pos: [6, 0, 5],
      state: 2
    },
    {
      pos: [6, 0, 6],
      state: 1
    },
    {
      pos: [7, 0, 0],
      state: 0
    },
    {
      pos: [7, 0, 1],
      state: 1
    },
    {
      pos: [7, 0, 2],
      state: 1
    },
    {
      pos: [7, 0, 3],
      state: 1
    },
    {
      pos: [7, 0, 4],
      state: 1
    },
    {
      pos: [7, 0, 5],
      state: 1
    },
    {
      pos: [7, 0, 6],
      state: 1
    },
    {
      pos: [7, 0, 7],
      state: 0
    },
    {
      pos: [8, 0, 0],
      state: 0
    },
    {
      pos: [8, 0, 1],
      state: 1
    },
    {
      pos: [8, 0, 2],
      state: 3
    },
    {
      pos: [8, 0, 3],
      state: 0
    },
    {
      pos: [8, 0, 4],
      state: 0
    },
    {
      pos: [8, 0, 5],
      state: 1
    },
    {
      pos: [8, 0, 6],
      state: 1
    },
    {
      pos: [8, 0, 7],
      state: 0
    },
    {
      pos: [9, 0, 0],
      state: 0
    },
    {
      pos: [9, 0, 1],
      state: 0
    },
    {
      pos: [9, 0, 6],
      state: 0
    },
    {
      pos: [9, 0, 7],
      state: 0
    },
    {
      pos: [0, 1, 0],
      state: 0
    },
    {
      pos: [0, 1, 7],
      state: 0
    },
    {
      pos: [1, 1, 0],
      state: 0
    },
    {
      pos: [1, 1, 7],
      state: 0
    },
    {
      pos: [2, 1, 2],
      state: 0
    },
    {
      pos: [2, 1, 3],
      state: 1
    },
    {
      pos: [2, 1, 4],
      state: 1
    },
    {
      pos: [2, 1, 5],
      state: 0
    },
    {
      pos: [3, 1, 2],
      state: 0
    },
    {
      pos: [3, 1, 3],
      state: 2
    },
    {
      pos: [3, 1, 4],
      state: 2
    },
    {
      pos: [3, 1, 5],
      state: 0
    },
    {
      pos: [4, 1, 2],
      state: 0
    },
    {
      pos: [4, 1, 3],
      state: 1
    },
    {
      pos: [4, 1, 4],
      state: 1
    },
    {
      pos: [4, 1, 5],
      state: 0
    },
    {
      pos: [5, 1, 2],
      state: 0
    },
    {
      pos: [5, 1, 3],
      state: 1
    },
    {
      pos: [5, 1, 4],
      state: 1
    },
    {
      pos: [5, 1, 5],
      state: 0
    },
    {
      pos: [6, 1, 2],
      state: 0
    },
    {
      pos: [6, 1, 3],
      state: 1
    },
    {
      pos: [6, 1, 4],
      state: 1
    },
    {
      pos: [6, 1, 5],
      state: 0
    },
    {
      pos: [8, 1, 0],
      state: 0
    },
    {
      pos: [8, 1, 7],
      state: 0
    },
    {
      pos: [9, 1, 0],
      state: 0
    },
    {
      pos: [9, 1, 1],
      state: 0
    },
    {
      pos: [9, 1, 6],
      state: 0
    },
    {
      pos: [9, 1, 7],
      state: 0
    },
    {
      pos: [0, 2, 0],
      state: 0
    },
    {
      pos: [0, 2, 7],
      state: 0
    },
    {
      pos: [3, 2, 2],
      state: 4
    },
    {
      pos: [3, 2, 5],
      state: 4
    },
    {
      pos: [9, 2, 0],
      state: 0
    },
    {
      pos: [9, 2, 7],
      state: 0
    },
    {
      pos: [3, 2, 3],
      state: 5
    },
    {
      pos: [3, 2, 4],
      state: 5
    },
    {
      pos: [4, 2, 2],
      state: 6
    },
    {
      pos: [4, 2, 3],
      state: 6
    },
    {
      pos: [4, 2, 4],
      state: 7
    },
    {
      pos: [4, 2, 5],
      state: 6
    },
    {
      pos: [3, 3, 1],
      state: 8
    },
    {
      pos: [3, 3, 2],
      state: 9
    },
    {
      pos: [3, 3, 5],
      state: 10
    },
    {
      pos: [3, 3, 6],
      state: 11
    },
    {
      pos: [3, 4, 2],
      state: 12
    },
    {
      pos: [3, 4, 3],
      state: 12
    },
    {
      pos: [3, 4, 4],
      state: 12
    },
    {
      pos: [3, 4, 5],
      state: 12
    },
    {
      nbt: {
        joint: "rollable",
        final_state: "minecraft:structure_void",
        name: "minecraft:connect_structure",
        pool: "minecraft:empty",
        id: "minecraft:jigsaw",
        target: "minecraft:empty"
      },
      pos: [0, 0, 3],
      state: 13
    },
    {
      nbt: {
        joint: "rollable",
        final_state: "minecraft:structure_void",
        name: "minecraft:connect_structure",
        pool: "minecraft:empty",
        id: "minecraft:jigsaw",
        target: "minecraft:empty"
      },
      pos: [0, 0, 5],
      state: 13
    }
  ],
  palette: [
    {
      Name: "minecraft:polished_deepslate"
    },
    {
      Properties: {
        axis: "y"
      },
      Name: "minecraft:deepslate"
    },
    {
      Name: "minecraft:cobbled_deepslate"
    },
    {
      Properties: {
        axis: "z"
      },
      Name: "minecraft:deepslate"
    },
    {
      Name: "minecraft:deepslate_tiles"
    },
    {
      Properties: {
        waterlogged: "false",
        type: "bottom"
      },
      Name: "minecraft:deepslate_tile_slab"
    },
    {
      Properties: {
        waterlogged: "false",
        lit: "false",
        candles: "1"
      },
      Name: "minecraft:white_candle"
    },
    {
      Properties: {
        waterlogged: "false",
        lit: "false",
        candles: "4"
      },
      Name: "minecraft:white_candle"
    },
    {
      Properties: {
        east: "none",
        waterlogged: "false",
        south: "low",
        north: "none",
        west: "none",
        up: "true"
      },
      Name: "minecraft:polished_deepslate_wall"
    },
    {
      Properties: {
        half: "top",
        waterlogged: "false",
        shape: "straight",
        facing: "north"
      },
      Name: "minecraft:deepslate_brick_stairs"
    },
    {
      Properties: {
        half: "top",
        waterlogged: "false",
        shape: "straight",
        facing: "south"
      },
      Name: "minecraft:deepslate_brick_stairs"
    },
    {
      Properties: {
        east: "none",
        waterlogged: "false",
        south: "none",
        north: "low",
        west: "none",
        up: "true"
      },
      Name: "minecraft:polished_deepslate_wall"
    },
    {
      Properties: {
        waterlogged: "false",
        type: "bottom"
      },
      Name: "minecraft:deepslate_brick_slab"
    },
    {
      Properties: {
        orientation: "west_up"
      },
      Name: "minecraft:jigsaw"
    }
  ],
  DataVersion: 3066
}